Workbook

Sheet Quarterly Performance
J1: Transposed List of Unique Customer Names
A2: Company | B2: Industry | C2: Revenue | D2: Profits | E2: Costs | F2: Customer Satisfaction Score(%) | G2: Market Share (%) | H2: Growth Potential (%) | I2: Stock Price ($) | J2: {=TRANSPOSE(_xlfn.UNIQUE($A3:$A1146))} -> Apex Capital Partners | K2: Ascend Capital Advisors | L2: Atlas Blockchain Services | M2: Atlas Community Bank | N2: Atlas Private Equity | O2: Atlas Risk Management | P2: BlueSky Banking Corp. | Q2: BlueSky Mobile Payments | R2: BlueSky Risk Solutions | S2: CrestPoint Blockchain Solutions | T2: CrestPoint Capital | U2: CryptoBridge Systems | V2: Evergreen Coverage Co. | W2: Evergreen Depository Services | X2: Evergreen Equity Group | Y2: Evergreen FinTech Group | Z2: Golden Gate Depository | AA2: Golden Gate Digital Finance | AB2: Golden Gate Insurance Partners | AC2: Granite State Credit Union | AD2: Guardian Life Assurance | AE2: GuardianPay Tech | AF2: GuardianPay Technologies | AG2: Harborview Savings Bank | AH2: Horizon Health & Life | AI2: Horizon National Bank | AJ2: Horizon Wealth Management | AK2: HorizonPay Tech | AL2: Ironclad Risk Solutions | AM2: Keystone Credit Union | AN2: Liberty Digital Finance | AO2: Liberty First Bank | AP2: Liberty Mutual Risk Partners | AQ2: Meridian Asset Solutions | AR2: NorthBridge Financial | AS2: NorthBridge Insurance Group | AT2: NorthStar Capital Partners | AU2: NorthStar Payment Systems | AV2: Nova Equity Management | AW2: NovaWallet Digital | AX2: Orion Investment Group | AY2: PaySphere Technologies | AZ2: Pinnacle Banking Group | BA2: Pinnacle Property & Casualty | BB2: Polaris Wealth Partners | BC2: Prairie Horizon Bank | BD2: Prairie Horizon Insurance | BE2: Riverstone Trust Co. | BF2: SafeHarbor Ins. Group | BG2: SafeHarbor Insurance Group | BH2: ShieldPoint Insurance | BI2: Silverline Asset Advisors | BJ2: Sterling Asset Management | BK2: Sterling FinTech Labs | BL2: Sterling L&H | BM2: Sterling Life & Health | BN2: Sterling Trust & Deposits | BO2: Summit Savings & Loan | BP2: SummitStone Digital Wallets | BQ2: SummitStone Investments | BR2: SummitStone Risk Advisors | BS2: SwiftPay | BT2: SwiftPay Solutions | BU2: Titan Global Investments | BV2: Titan Global Invsts. | BW2: Titan Reinsurance Corp. | BX2: TitanPay Innovations | BY2: Unity Federal Credit Union | BZ2: Vanguard Wealth Strategies
A3: Apex Capital Partners | B3: Investment & Asset Management | C3: 2.4774974e+08 | D3: 12182989 | E3: =C3-D3 -> 2.3556675e+08 | F3: 18.174109 | G3: 32.939703 | H3: 7.3444336 | I3: 19.145243 | J3: =IF($A3=J$2,1,0) -> 1 | K3: =IF($A3=K$2,1,0) -> 0 | L3: =IF($A3=L$2,1,0) -> 0 | M3: =IF($A3=M$2,1,0) -> 0 | N3: =IF($A3=N$2,1,0) -> 0 | O3: =IF($A3=O$2,1,0) -> 0 | P3: =IF($A3=P$2,1,0) -> 0 | Q3: =IF($A3=Q$2,1,0) -> 0 | ... BZ3: =IF($A3=BZ$2,1,0) -> 0
A4: Apex Capital Partners | B4: Investment & Asset Management | C4: 2.505283e+08 | D4: 12793593 | E4: =C4-D4 -> 2.3773471e+08 | F4: 60.138705 | G4: 32.453607 | H4: 5.8531139 | I4: 27.241833 | J4: =IF($A4=J$2,1,0) -> 1 | K4: =IF($A4=K$2,1,0) -> 0 | L4: =IF($A4=L$2,1,0) -> 0 | M4: =IF($A4=M$2,1,0) -> 0 | N4: =IF($A4=N$2,1,0) -> 0 | O4: =IF($A4=O$2,1,0) -> 0 | P4: =IF($A4=P$2,1,0) -> 0 | Q4: =IF($A4=Q$2,1,0) -> 0 | ... BZ4: =IF($A4=BZ$2,1,0) -> 0
A5: Apex Capital Partners | B5: Investment & Asset Management | C5: 2.4052715e+08 | D5: =C5-E5 -> 84083612 | E5: 1.5644354e+08 | F5: 19.604072 | G5: 32.781267 | H5: 5.6798574 | I5: 35.652206 | J5: =IF($A5=J$2,1,0) -> 1 | K5: =IF($A5=K$2,1,0) -> 0 | L5: =IF($A5=L$2,1,0) -> 0 | M5: =IF($A5=M$2,1,0) -> 0 | N5: =IF($A5=N$2,1,0) -> 0 | O5: =IF($A5=O$2,1,0) -> 0 | P5: =IF($A5=P$2,1,0) -> 0 | Q5: =IF($A5=Q$2,1,0) -> 0 | ... BZ5: =IF($A5=BZ$2,1,0) -> 0
A6: Apex Capital Partners | B6: Investment & Asset Management | C6: 2.6934109e+08 | D6: 12903441 | E6: =C6-D6 -> 2.5643765e+08 | F6: 32.470632 | G6: 34.407901 | H6: 5.8982647 | I6: 39.35643 | J6: =IF($A6=J$2,1,0) -> 1 | K6: =IF($A6=K$2,1,0) -> 0 | L6: =IF($A6=L$2,1,0) -> 0 | M6: =IF($A6=M$2,1,0) -> 0 | N6: =IF($A6=N$2,1,0) -> 0 | O6: =IF($A6=O$2,1,0) -> 0 | P6: =IF($A6=P$2,1,0) -> 0 | Q6: =IF($A6=Q$2,1,0) -> 0 | ... BZ6: =IF($A6=BZ$2,1,0) -> 0
A7: Apex Capital Partners | B7: Investment & Asset Management | C7: 2.032438e+08 | D7: =C7-E7 -> 39655154 | E7: 1.6358865e+08 | F7: 63.476778 | G7: 0.36828509 | H7: 4.2349601 | I7: 40.309513 | J7: =IF($A7=J$2,1,0) -> 1 | K7: =IF($A7=K$2,1,0) -> 0 | L7: =IF($A7=L$2,1,0) -> 0 | M7: =IF($A7=M$2,1,0) -> 0 | N7: =IF($A7=N$2,1,0) -> 0 | O7: =IF($A7=O$2,1,0) -> 0 | P7: =IF($A7=P$2,1,0) -> 0 | Q7: =IF($A7=Q$2,1,0) -> 0 | ... BZ7: =IF($A7=BZ$2,1,0) -> 0
A8: Apex Capital Partners | B8: Investment & Asset Management | C8: 2.4285012e+08 | D8: =C8-E8 -> 78442525 | E8: 1.6440759e+08 | F8: 69.999336 | G8: 31.013721 | H8: 4.9613178 | I8: 41.07959 | J8: =IF($A8=J$2,1,0) -> 1 | K8: =IF($A8=K$2,1,0) -> 0 | L8: =IF($A8=L$2,1,0) -> 0 | M8: =IF($A8=M$2,1,0) -> 0 | N8: =IF($A8=N$2,1,0) -> 0 | O8: =IF($A8=O$2,1,0) -> 0 | P8: =IF($A8=P$2,1,0) -> 0 | Q8: =IF($A8=Q$2,1,0) -> 0 | ... BZ8: =IF($A8=BZ$2,1,0) -> 0
A9: Apex Capital Partners | B9: Investment & Asset Management | C9: 2.5959981e+08 | D9: =C9-E9 -> 95331036 | E9: 1.6426878e+08 | F9: 68.559223 | G9: 33.839917 | H9: 688.80462 | I9: 41.289074 | J9: =IF($A9=J$2,1,0) -> 1 | K9: =IF($A9=K$2,1,0) -> 0 | L9: =IF($A9=L$2,1,0) -> 0 | M9: =IF($A9=M$2,1,0) -> 0 | N9: =IF($A9=N$2,1,0) -> 0 | O9: =IF($A9=O$2,1,0) -> 0 | P9: =IF($A9=P$2,1,0) -> 0 | Q9: =IF($A9=Q$2,1,0) -> 0 | ... BZ9: =IF($A9=BZ$2,1,0) -> 0
A10: Apex Capital Partners | B10: Investment & Asset Management | C10: 2.2985332e+08 | D10: 11623384 | E10: =C10-D10 -> 2.1822993e+08 | F10: 38.269989 | G10: 30.615904 | H10: 6.8587482 | I10: 43.218911 | J10: =IF($A10=J$2,1,0) -> 1 | K10: =IF($A10=K$2,1,0) -> 0 | L10: =IF($A10=L$2,1,0) -> 0 | M10: =IF($A10=M$2,1,0) -> 0 | N10: =IF($A10=N$2,1,0) -> 0 | O10: =IF($A10=O$2,1,0) -> 0 | P10: =IF($A10=P$2,1,0) -> 0 | Q10: =IF($A10=Q$2,1,0) -> 0 | ... BZ10: =IF($A10=BZ$2,1,0) -> 0
A11: Apex Capital Partners | B11: Investment & Asset Management | C11: 2.5901078e+08 | D11: =C11-E11 -> 98459462 | E11: 1.6055132e+08 | F11: 18.399015 | G11: 25.6962 | H11: 7.0106137 | I11: 44.934124 | J11: =IF($A11=J$2,1,0) -> 1 | K11: =IF($A11=K$2,1,0) -> 0 | L11: =IF($A11=L$2,1,0) -> 0 | M11: =IF($A11=M$2,1,0) -> 0 | N11: =IF($A11=N$2,1,0) -> 0 | O11: =IF($A11=O$2,1,0) -> 0 | P11: =IF($A11=P$2,1,0) -> 0 | Q11: =IF($A11=Q$2,1,0) -> 0 | ... BZ11: =IF($A11=BZ$2,1,0) -> 0
A12: Apex Capital Partners | B12: Investment & Asset Management | C12: 2.6129792e+08 | D12: 12294407 | E12: =C12-D12 -> 2.4900352e+08 | F12: 51.849987 | G12: 29.709224 | H12: 7.4503661 | I12: 46.072482 | J12: =IF($A12=J$2,1,0) -> 1 | K12: =IF($A12=K$2,1,0) -> 0 | L12: =IF($A12=L$2,1,0) -> 0 | M12: =IF($A12=M$2,1,0) -> 0 | N12: =IF($A12=N$2,1,0) -> 0 | O12: =IF($A12=O$2,1,0) -> 0 | P12: =IF($A12=P$2,1,0) -> 0 | Q12: =IF($A12=Q$2,1,0) -> 0 | ... BZ12: =IF($A12=BZ$2,1,0) -> 0
A13: Apex Capital Partners | B13: Investment & Asset Management | C13: 2.5534944e+08 | D13: 12409813 | E13: =C13-D13 -> 2.4293963e+08 | F13: 34.404261 | G13: 0.45398678 | H13: 5.0253145 | I13: 46.598314 | J13: =IF($A13=J$2,1,0) -> 1 | K13: =IF($A13=K$2,1,0) -> 0 | L13: =IF($A13=L$2,1,0) -> 0 | M13: =IF($A13=M$2,1,0) -> 0 | N13: =IF($A13=N$2,1,0) -> 0 | O13: =IF($A13=O$2,1,0) -> 0 | P13: =IF($A13=P$2,1,0) -> 0 | Q13: =IF($A13=Q$2,1,0) -> 0 | ... BZ13: =IF($A13=BZ$2,1,0) -> 0
A14: Apex Capital Partners | B14: Investment & Asset Management | C14: 2.328779e+08 | D14: 13779425 | E14: =C14-D14 -> 2.1909847e+08 | F14: 25.055651 | G14: 32.097077 | H14: 3.5272792 | I14: 47.379051 | J14: =IF($A14=J$2,1,0) -> 1 | K14: =IF($A14=K$2,1,0) -> 0 | L14: =IF($A14=L$2,1,0) -> 0 | M14: =IF($A14=M$2,1,0) -> 0 | N14: =IF($A14=N$2,1,0) -> 0 | O14: =IF($A14=O$2,1,0) -> 0 | P14: =IF($A14=P$2,1,0) -> 0 | Q14: =IF($A14=Q$2,1,0) -> 0 | ... BZ14: =IF($A14=BZ$2,1,0) -> 0
A15: Apex Capital Partners | B15: Investment & Asset Management | C15: 2.8161644e+08 | D15: =C15-E15 -> 1.2173523e+08 | E15: 1.5988121e+08 | F15: 100 | G15: 0.34048647 | H15: 3.1942242 | I15: 47.618958 | J15: =IF($A15=J$2,1,0) -> 1 | K15: =IF($A15=K$2,1,0) -> 0 | L15: =IF($A15=L$2,1,0) -> 0 | M15: =IF($A15=M$2,1,0) -> 0 | N15: =IF($A15=N$2,1,0) -> 0 | O15: =IF($A15=O$2,1,0) -> 0 | P15: =IF($A15=P$2,1,0) -> 0 | Q15: =IF($A15=Q$2,1,0) -> 0 | ... BZ15: =IF($A15=BZ$2,1,0) -> 0
A16: Apex Capital Partners | B16: Investment & Asset Management | C16: 2.5017249e+08 | D16: =C16-E16 -> 86623191 | E16: 1.635493e+08 | F16: 51.413709 | G16: 37.112942 | H16: 5.3009657 | I16: 48.092019 | J16: =IF($A16=J$2,1,0) -> 1 | K16: =IF($A16=K$2,1,0) -> 0 | L16: =IF($A16=L$2,1,0) -> 0 | M16: =IF($A16=M$2,1,0) -> 0 | N16: =IF($A16=N$2,1,0) -> 0 | O16: =IF($A16=O$2,1,0) -> 0 | P16: =IF($A16=P$2,1,0) -> 0 | Q16: =IF($A16=Q$2,1,0) -> 0 | ... BZ16: =IF($A16=BZ$2,1,0) -> 0
A17: Apex Capital Partners | B17: Investment & Asset Management | C17: 2.6065468e+08 | D17: =C17-E17 -> 95583636 | E17: 1.6507104e+08 | F17: 41.560718 | G17: 30.668518 | H17: 387.18324 | I17: 48.832514 | J17: =IF($A17=J$2,1,0) -> 1 | K17: =IF($A17=K$2,1,0) -> 0 | L17: =IF($A17=L$2,1,0) -> 0 | M17: =IF($A17=M$2,1,0) -> 0 | N17: =IF($A17=N$2,1,0) -> 0 | O17: =IF($A17=O$2,1,0) -> 0 | P17: =IF($A17=P$2,1,0) -> 0 | Q17: =IF($A17=Q$2,1,0) -> 0 | ... BZ17: =IF($A17=BZ$2,1,0) -> 0
A18: Apex Capital Partners | B18: Investment & Asset Management | C18: 2.3496279e+08 | D18: 11055519 | E18: =C18-D18 -> 2.2390727e+08 | F18: 100 | G18: 38.351475 | H18: 3.3093938 | I18: 53.846885 | J18: =IF($A18=J$2,1,0) -> 1 | K18: =IF($A18=K$2,1,0) -> 0 | L18: =IF($A18=L$2,1,0) -> 0 | M18: =IF($A18=M$2,1,0) -> 0 | N18: =IF($A18=N$2,1,0) -> 0 | O18: =IF($A18=O$2,1,0) -> 0 | P18: =IF($A18=P$2,1,0) -> 0 | Q18: =IF($A18=Q$2,1,0) -> 0 | ... BZ18: =IF($A18=BZ$2,1,0) -> 0
A19: Apex Capital Partners | B19: Investment & Asset Management | C19: 2.4001577e+08 | D19: 12236256 | E19: =C19-D19 -> 2.2777951e+08 | F19: 63.360848 | G19: 28.340815 | H19: 433.34181 | I19: 54.190413 | J19: =IF($A19=J$2,1,0) -> 1 | K19: =IF($A19=K$2,1,0) -> 0 | L19: =IF($A19=L$2,1,0) -> 0 | M19: =IF($A19=M$2,1,0) -> 0 | N19: =IF($A19=N$2,1,0) -> 0 | O19: =IF($A19=O$2,1,0) -> 0 | P19: =IF($A19=P$2,1,0) -> 0 | Q19: =IF($A19=Q$2,1,0) -> 0 | ... BZ19: =IF($A19=BZ$2,1,0) -> 0
A20: Apex Capital Partners | B20: Investment & Asset Management | C20: 2.1035666e+08 | D20: =C20-E20 -> 43384476 | E20: 1.6697219e+08 | F20: 100 | G20: 37.794227 | H20: 2.3773843 | I20: 62.409896 | J20: =IF($A20=J$2,1,0) -> 1 | K20: =IF($A20=K$2,1,0) -> 0 | L20: =IF($A20=L$2,1,0) -> 0 | M20: =IF($A20=M$2,1,0) -> 0 | N20: =IF($A20=N$2,1,0) -> 0 | O20: =IF($A20=O$2,1,0) -> 0 | P20: =IF($A20=P$2,1,0) -> 0 | Q20: =IF($A20=Q$2,1,0) -> 0 | ... BZ20: =IF($A20=BZ$2,1,0) -> 0
A21: Apex Capital Partners | B21: Investment & Asset Management | C21: 2.8789081e+08 | D21: =C21-E21 -> 1.2652042e+08 | E21: 1.6137038e+08 | F21: 71.57063 | G21: 0.33727384 | H21: 4.1859898 | I21: 66.137796 | J21: =IF($A21=J$2,1,0) -> 1 | K21: =IF($A21=K$2,1,0) -> 0 | L21: =IF($A21=L$2,1,0) -> 0 | M21: =IF($A21=M$2,1,0) -> 0 | N21: =IF($A21=N$2,1,0) -> 0 | O21: =IF($A21=O$2,1,0) -> 0 | P21: =IF($A21=P$2,1,0) -> 0 | Q21: =IF($A21=Q$2,1,0) -> 0 | ... BZ21: =IF($A21=BZ$2,1,0) -> 0
A22: Ascend Capital Advisors | B22: Investment & Asset Management | C22: 2.5106556e+08 | D22: =C22-E22 -> 91337339 | E22: 1.5972822e+08 | F22: 49.900688 | G22: 49.612975 | H22: 1.2365358 | I22: 36.111244 | J22: =IF($A22=J$2,1,0) -> 0 | K22: =IF($A22=K$2,1,0) -> 1 | L22: =IF($A22=L$2,1,0) -> 0 | M22: =IF($A22=M$2,1,0) -> 0 | N22: =IF($A22=N$2,1,0) -> 0 | O22: =IF($A22=O$2,1,0) -> 0 | P22: =IF($A22=P$2,1,0) -> 0 | Q22: =IF($A22=Q$2,1,0) -> 0 | ... BZ22: =IF($A22=BZ$2,1,0) -> 0
A23: Ascend Capital Advisors | B23: Investment & Asset Management | C23: 2.3321826e+08 | D23: =C23-E23 -> 62763832 | E23: 1.7045443e+08 | F23: 100 | G23: 40.005825 | H23: 8.7984706 | I23: 38.612734 | J23: =IF($A23=J$2,1,0) -> 0 | K23: =IF($A23=K$2,1,0) -> 1 | L23: =IF($A23=L$2,1,0) -> 0 | M23: =IF($A23=M$2,1,0) -> 0 | N23: =IF($A23=N$2,1,0) -> 0 | O23: =IF($A23=O$2,1,0) -> 0 | P23: =IF($A23=P$2,1,0) -> 0 | Q23: =IF($A23=Q$2,1,0) -> 0 | ... BZ23: =IF($A23=BZ$2,1,0) -> 0
A24: Ascend Capital Advisors | B24: Investment & Asset Management | C24: 2.6446819e+08 | D24: =C24-E24 -> 98512100 | E24: 1.6595609e+08 | F24: 14.946762 | G24: 43.895945 | H24: 3.8644883 | I24: 39.245364 | J24: =IF($A24=J$2,1,0) -> 0 | K24: =IF($A24=K$2,1,0) -> 1 | L24: =IF($A24=L$2,1,0) -> 0 | M24: =IF($A24=M$2,1,0) -> 0 | N24: =IF($A24=N$2,1,0) -> 0 | O24: =IF($A24=O$2,1,0) -> 0 | P24: =IF($A24=P$2,1,0) -> 0 | Q24: =IF($A24=Q$2,1,0) -> 0 | ... BZ24: =IF($A24=BZ$2,1,0) -> 0
A25: Ascend Capital Advisors | B25: Investment & Asset Management | C25: 2.3064354e+08 | D25: 12761330 | E25: =C25-D25 -> 2.1788221e+08 | F25: 100 | G25: 35.106357 | H25: 797.25631 | I25: 41.655969 | J25: =IF($A25=J$2,1,0) -> 0 | K25: =IF($A25=K$2,1,0) -> 1 | L25: =IF($A25=L$2,1,0) -> 0 | M25: =IF($A25=M$2,1,0) -> 0 | N25: =IF($A25=N$2,1,0) -> 0 | O25: =IF($A25=O$2,1,0) -> 0 | P25: =IF($A25=P$2,1,0) -> 0 | Q25: =IF($A25=Q$2,1,0) -> 0 | ... BZ25: =IF($A25=BZ$2,1,0) -> 0
A26: Ascend Capital Advisors | B26: Investment & Asset Management | C26: 2.507027e+08 | D26: 14356170 | E26: =C26-D26 -> 2.3634653e+08 | F26: 100 | G26: 45.756634 | H26: 4.3007112 | I26: 41.751786 | J26: =IF($A26=J$2,1,0) -> 0 | K26: =IF($A26=K$2,1,0) -> 1 | L26: =IF($A26=L$2,1,0) -> 0 | M26: =IF($A26=M$2,1,0) -> 0 | N26: =IF($A26=N$2,1,0) -> 0 | O26: =IF($A26=O$2,1,0) -> 0 | P26: =IF($A26=P$2,1,0) -> 0 | Q26: =IF($A26=Q$2,1,0) -> 0 | ... BZ26: =IF($A26=BZ$2,1,0) -> 0
A27: Ascend Capital Advisors | B27: Investment & Asset Management | C27: 2.4014766e+08 | D27: 13647690 | E27: =C27-D27 -> 2.2649997e+08 | F27: 57.561085 | G27: 43.937187 | H27: 3.288441 | I27: 42.77253 | J27: =IF($A27=J$2,1,0) -> 0 | K27: =IF($A27=K$2,1,0) -> 1 | L27: =IF($A27=L$2,1,0) -> 0 | M27: =IF($A27=M$2,1,0) -> 0 | N27: =IF($A27=N$2,1,0) -> 0 | O27: =IF($A27=O$2,1,0) -> 0 | P27: =IF($A27=P$2,1,0) -> 0 | Q27: =IF($A27=Q$2,1,0) -> 0 | ... BZ27: =IF($A27=BZ$2,1,0) -> 0
A28: Ascend Capital Advisors | B28: Investment & Asset Management | C28: 2.6358774e+08 | D28: =C28-E28 -> 1.0987674e+08 | E28: 1.53711e+08 | F28: 67.79836 | G28: 0.30602275 | H28: 4.9115463 | I28: 44.98894 | J28: =IF($A28=J$2,1,0) -> 0 | K28: =IF($A28=K$2,1,0) -> 1 | L28: =IF($A28=L$2,1,0) -> 0 | M28: =IF($A28=M$2,1,0) -> 0 | N28: =IF($A28=N$2,1,0) -> 0 | O28: =IF($A28=O$2,1,0) -> 0 | P28: =IF($A28=P$2,1,0) -> 0 | Q28: =IF($A28=Q$2,1,0) -> 0 | ... BZ28: =IF($A28=BZ$2,1,0) -> 0
A29: Ascend Capital Advisors | B29: Investment & Asset Management | C29: 2.2374623e+08 | D29: =C29-E29 -> 60035519 | E29: 1.6371071e+08 | F29: 100 | G29: 50.204209 | H29: 3.3567706 | I29: 45.895838 | J29: =IF($A29=J$2,1,0) -> 0 | K29: =IF($A29=K$2,1,0) -> 1 | L29: =IF($A29=L$2,1,0) -> 0 | M29: =IF($A29=M$2,1,0) -> 0 | N29: =IF($A29=N$2,1,0) -> 0 | O29: =IF($A29=O$2,1,0) -> 0 | P29: =IF($A29=P$2,1,0) -> 0 | Q29: =IF($A29=Q$2,1,0) -> 0 | ... BZ29: =IF($A29=BZ$2,1,0) -> 0
A30: Ascend Capital Advisors | B30: Investment & Asset Management | C30: 2.75354e+08 | D30: =C30-E30 -> 1.0891827e+08 | E30: 1.6643574e+08 | F30: 40.803761 | G30: 48.905377 | H30: 860.82742 | I30: 46.766618 | J30: =IF($A30=J$2,1,0) -> 0 | K30: =IF($A30=K$2,1,0) -> 1 | L30: =IF($A30=L$2,1,0) -> 0 | M30: =IF($A30=M$2,1,0) -> 0 | N30: =IF($A30=N$2,1,0) -> 0 | O30: =IF($A30=O$2,1,0) -> 0 | P30: =IF($A30=P$2,1,0) -> 0 | Q30: =IF($A30=Q$2,1,0) -> 0 | ... BZ30: =IF($A30=BZ$2,1,0) -> 0
A31: Ascend Capital Advisors | B31: Investment & Asset Management | C31: 2.3362921e+08 | D31: =C31-E31 -> 57847816 | E31: 1.757814e+08 | F31: 100 | G31: 45.414144 | H31: 2.6753709 | I31: 47.516792 | J31: =IF($A31=J$2,1,0) -> 0 | K31: =IF($A31=K$2,1,0) -> 1 | L31: =IF($A31=L$2,1,0) -> 0 | M31: =IF($A31=M$2,1,0) -> 0 | N31: =IF($A31=N$2,1,0) -> 0 | O31: =IF($A31=O$2,1,0) -> 0 | P31: =IF($A31=P$2,1,0) -> 0 | Q31: =IF($A31=Q$2,1,0) -> 0 | ... BZ31: =IF($A31=BZ$2,1,0) -> 0
A32: Ascend Capital Advisors | B32: Investment & Asset Management | C32: 2.4190419e+08 | D32: =C32-E32 -> 75727253 | E32: 1.6617693e+08 | F32: 100 | G32: 40.956264 | H32: 0.94963735 | I32: 47.516792 | J32: =IF($A32=J$2,1,0) -> 0 | K32: =IF($A32=K$2,1,0) -> 1 | L32: =IF($A32=L$2,1,0) -> 0 | M32: =IF($A32=M$2,1,0) -> 0 | N32: =IF($A32=N$2,1,0) -> 0 | O32: =IF($A32=O$2,1,0) -> 0 | P32: =IF($A32=P$2,1,0) -> 0 | Q32: =IF($A32=Q$2,1,0) -> 0 | ... BZ32: =IF($A32=BZ$2,1,0) -> 0
A33: Ascend Capital Advisors | B33: Investment & Asset Management | C33: 2.3663475e+08 | D33: 11303022 | E33: =C33-D33 -> 2.2533173e+08 | F33: 49.598694 | G33: 45.68605 | H33: 1.6039229 | I33: 47.516792 | J33: =IF($A33=J$2,1,0) -> 0 | K33: =IF($A33=K$2,1,0) -> 1 | L33: =IF($A33=L$2,1,0) -> 0 | M33: =IF($A33=M$2,1,0) -> 0 | N33: =IF($A33=N$2,1,0) -> 0 | O33: =IF($A33=O$2,1,0) -> 0 | P33: =IF($A33=P$2,1,0) -> 0 | Q33: =IF($A33=Q$2,1,0) -> 0 | ... BZ33: =IF($A33=BZ$2,1,0) -> 0
A34: Ascend Capital Advisors | B34: Investment & Asset Management | C34: 2.638053e+08 | D34: =C34-E34 -> 1.1025273e+08 | E34: 1.5355257e+08 | F34: 35.719723 | G34: 45.464528 | H34: 3.2555649 | I34: 47.516792 | J34: =IF($A34=J$2,1,0) -> 0 | K34: =IF($A34=K$2,1,0) -> 1 | L34: =IF($A34=L$2,1,0) -> 0 | M34: =IF($A34=M$2,1,0) -> 0 | N34: =IF($A34=N$2,1,0) -> 0 | O34: =IF($A34=O$2,1,0) -> 0 | P34: =IF($A34=P$2,1,0) -> 0 | Q34: =IF($A34=Q$2,1,0) -> 0 | ... BZ34: =IF($A34=BZ$2,1,0) -> 0
A35: Ascend Capital Advisors | B35: Investment & Asset Management | C35: 2.1991773e+08 | D35: =C35-E35 -> 48885674 | E35: 1.7103206e+08 | F35: 100 | G35: 44.939349 | H35: 7.4352217 | I35: 48.570326 | J35: =IF($A35=J$2,1,0) -> 0 | K35: =IF($A35=K$2,1,0) -> 1 | L35: =IF($A35=L$2,1,0) -> 0 | M35: =IF($A35=M$2,1,0) -> 0 | N35: =IF($A35=N$2,1,0) -> 0 | O35: =IF($A35=O$2,1,0) -> 0 | P35: =IF($A35=P$2,1,0) -> 0 | Q35: =IF($A35=Q$2,1,0) -> 0 | ... BZ35: =IF($A35=BZ$2,1,0) -> 0
A36: Ascend Capital Advisors | B36: Investment & Asset Management | C36: 2.481852e+08 | D36: 12481549 | E36: =C36-D36 -> 2.3570365e+08 | F36: 34.19378 | G36: 48.901174 | H36: 3.046129 | I36: 49.560224 | J36: =IF($A36=J$2,1,0) -> 0 | K36: =IF($A36=K$2,1,0) -> 1 | L36: =IF($A36=L$2,1,0) -> 0 | M36: =IF($A36=M$2,1,0) -> 0 | N36: =IF($A36=N$2,1,0) -> 0 | O36: =IF($A36=O$2,1,0) -> 0 | P36: =IF($A36=P$2,1,0) -> 0 | Q36: =IF($A36=Q$2,1,0) -> 0 | ... BZ36: =IF($A36=BZ$2,1,0) -> 0
A37: Ascend Capital Advisors | B37: Investment & Asset Management | C37: 2.2784605e+08 | D37: 12652198 | E37: =C37-D37 -> 2.1519385e+08 | F37: 47.022033 | G37: 43.061967 | H37: 6.8095022 | I37: 50.110579 | J37: =IF($A37=J$2,1,0) -> 0 | K37: =IF($A37=K$2,1,0) -> 1 | L37: =IF($A37=L$2,1,0) -> 0 | M37: =IF($A37=M$2,1,0) -> 0 | N37: =IF($A37=N$2,1,0) -> 0 | O37: =IF($A37=O$2,1,0) -> 0 | P37: =IF($A37=P$2,1,0) -> 0 | Q37: =IF($A37=Q$2,1,0) -> 0 | ... BZ37: =IF($A37=BZ$2,1,0) -> 0
A38: Ascend Capital Advisors | B38: Investment & Asset Management | C38: 2.5983872e+08 | D38: 13130176 | E38: =C38-D38 -> 2.4670855e+08 | F38: 44.997815 | G38: 0.45744103 | H38: 0.33470299 | I38: 55.421811 | J38: =IF($A38=J$2,1,0) -> 0 | K38: =IF($A38=K$2,1,0) -> 1 | L38: =IF($A38=L$2,1,0) -> 0 | M38: =IF($A38=M$2,1,0) -> 0 | N38: =IF($A38=N$2,1,0) -> 0 | O38: =IF($A38=O$2,1,0) -> 0 | P38: =IF($A38=P$2,1,0) -> 0 | Q38: =IF($A38=Q$2,1,0) -> 0 | ... BZ38: =IF($A38=BZ$2,1,0) -> 0
A39: Ascend Capital Advisors | B39: Investment & Asset Management | C39: 2.5800445e+08 | D39: =C39-E39 -> 1.0266779e+08 | E39: 1.5533666e+08 | F39: 26.353828 | G39: 42.327395 | H39: 4.7233589 | I39: 57.553447 | J39: =IF($A39=J$2,1,0) -> 0 | K39: =IF($A39=K$2,1,0) -> 1 | L39: =IF($A39=L$2,1,0) -> 0 | M39: =IF($A39=M$2,1,0) -> 0 | N39: =IF($A39=N$2,1,0) -> 0 | O39: =IF($A39=O$2,1,0) -> 0 | P39: =IF($A39=P$2,1,0) -> 0 | Q39: =IF($A39=Q$2,1,0) -> 0 | ... BZ39: =IF($A39=BZ$2,1,0) -> 0
A40: Ascend Capital Advisors | B40: Investment & Asset Management | C40: 2.6356627e+08 | D40: =C40-E40 -> 1.039433e+08 | E40: 1.5962296e+08 | F40: 73.09948 | G40: 43.767441 | H40: 1.6132018 | I40: 59.642141 | J40: =IF($A40=J$2,1,0) -> 0 | K40: =IF($A40=K$2,1,0) -> 1 | L40: =IF($A40=L$2,1,0) -> 0 | M40: =IF($A40=M$2,1,0) -> 0 | N40: =IF($A40=N$2,1,0) -> 0 | O40: =IF($A40=O$2,1,0) -> 0 | P40: =IF($A40=P$2,1,0) -> 0 | Q40: =IF($A40=Q$2,1,0) -> 0 | ... BZ40: =IF($A40=BZ$2,1,0) -> 0
...

Sheet Average Annual Performance
A1: Company | B1: Average of Revenue | C1: Average of Profits | D1: Average of Costs | E1: Average of Customer Satisfaction Score | F1: Average of Market Share | G1: Average of Growth Potential | H1: Average of Stock Price | I1: Customer Satifaction Ranking | J1: Reveune Ranking | K1: Profit Ranking | L1: Cost Ranking | M1: Stock Price Ranking | N1: Market Share ZScore Normalizaton | O1: Growth Potential ZScore Normailzaton | P1: BCG Group
A2: {=_xlfn.UNIQUE('Quarterly Performance'!A3:A1146)} -> Apex Capital Partners | B2: =AVERAGEIF('Quarterly Performance'!$J$3:$J$1146, 1, 'Quarterly Performance'!C$3:C$1146) -> 2.4831047e+08 | C2: =AVERAGEIF('Quarterly Performance'!$J$3:$J$1146, 1, 'Quarterly Performance'!D$3:D$1146) -> 51636714 | D2: =AVERAGEIF('Quarterly Performance'!$J$3:$J$1146, 1, 'Quarterly Performance'!E$3:E$1146) -> 1.9667376e+08 | E2: =AVERAGEIF('Quarterly Performance'!$J$3:$J$1146, 1, 'Quarterly Performance'!F$3:F$1146) -> 54.121456 | F2: =AVERAGEIF('Quarterly Performance'!$J$3:$J$1146, 1, 'Quarterly Performance'!G$3:G$1146) -> 25.753817 | G2: =AVERAGEIF('Quarterly Performance'!$J$3:$J$1146, 1, 'Quarterly Performance'!H$3:H$1146) -> 83.765363 | H2: =AVERAGEIF('Quarterly Performance'!$J$3:$J$1146, 1, 'Quarterly Performance'!I$3:I$1146) -> 44.916066 | I2: =IF(E2 <Percentiles!$E$3, "Low", IF(E2 <= Percentiles!$E$4, "Medium", "High")) -> Low | J2: =IF(B2 <Percentiles!B$3, "Low", IF(B2 <= Percentiles!B$4, "Medium", "High")) -> Medium | K2: =IF(C2 <Percentiles!C$3, "Low", IF(C2 <= Percentiles!C$4, "Medium", "High")) -> Medium | L2: =IF(D2 <Percentiles!D$3, "Low", IF(D2 <= Percentiles!D$4, "Medium", "High")) -> Medium | M2: =IF(H2 <Percentiles!$H$3, "Low", IF(H2 <= Percentiles!$H$4, "Medium", "High")) -> Low | N2: =(F2 - AVERAGE(F$2:$F$70)) / _xlfn.STDEV.S(F$2:F$70) -> -1.1157592 | O2: =(G2 - AVERAGE($G$2:G$70)) / _xlfn.STDEV.S(G$2:G$70) -> -0.41662273 | P2: =IF(AND(N2>=0, O2>=0), "Star", IF(AND(N2>=0, O2<0), "Cash Cow", IF(AND(N2<0, O2>=0), "Question Mark", "Dog"))) -> Dog
A3: Ascend Capital Advisors | B3: =AVERAGEIF('Quarterly Performance'!$K$3:$K$1146, 1, 'Quarterly Performance'!C$3:C$1146) -> 2.4587496e+08 | C3: =AVERAGEIF('Quarterly Performance'!$K$3:$K$1146, 1, 'Quarterly Performance'!D$3:D$1146) -> 56676714 | D3: =AVERAGEIF('Quarterly Performance'!$K$3:$K$1146, 1, 'Quarterly Performance'!E$3:E$1146) -> 1.8919825e+08 | E3: =AVERAGEIF('Quarterly Performance'!$K$3:$K$1146, 1, 'Quarterly Performance'!F$3:F$1146) -> 67.0998 | F3: =AVERAGEIF('Quarterly Performance'!$K$3:$K$1146, 1, 'Quarterly Performance'!G$3:G$1146) -> 37.959194 | G3: =AVERAGEIF('Quarterly Performance'!$K$3:$K$1146, 1, 'Quarterly Performance'!H$3:H$1146) -> 86.251134 | H3: =AVERAGEIF('Quarterly Performance'!$K$3:$K$1146, 1, 'Quarterly Performance'!I$3:I$1146) -> 47.516792 | I3: =IF(E3 <Percentiles!$E$3, "Low", IF(E3 <= Percentiles!$E$4, "Medium", "High")) -> High | J3: =IF(B3 <Percentiles!B$3, "Low", IF(B3 <= Percentiles!B$4, "Medium", "High")) -> Low | K3: =IF(C3 <Percentiles!C$3, "Low", IF(C3 <= Percentiles!C$4, "Medium", "High")) -> High | L3: =IF(D3 <Percentiles!D$3, "Low", IF(D3 <= Percentiles!D$4, "Medium", "High")) -> Low | M3: =IF(H3 <Percentiles!$H$3, "Low", IF(H3 <= Percentiles!$H$4, "Medium", "High")) -> Low | N3: =(F3 - AVERAGE(F$2:$F$70)) / _xlfn.STDEV.S(F$2:F$70) -> 1.0022244 | O3: =(G3 - AVERAGE($G$2:G$70)) / _xlfn.STDEV.S(G$2:G$70) -> -0.37274038 | P3: =IF(AND(N3>=0, O3>=0), "Star", IF(AND(N3>=0, O3<0), "Cash Cow", IF(AND(N3<0, O3>=0), "Question Mark", "Dog"))) -> Cash Cow
A4: Atlas Blockchain Services | B4: =AVERAGEIF('Quarterly Performance'!L$3:L$1146, 1, 'Quarterly Performance'!C$3:C$1146) -> 2.4893945e+08 | C4: =AVERAGEIF('Quarterly Performance'!$L$3:$L$1146, 1, 'Quarterly Performance'!D$3:D$1146) -> 46844787 | D4: =AVERAGEIF('Quarterly Performance'!$L$3:$L$1146, 1, 'Quarterly Performance'!E$3:E$1146) -> 2.0209466e+08 | E4: =AVERAGEIF('Quarterly Performance'!$L$3:$L$1146, 1, 'Quarterly Performance'!F$3:F$1146) -> 69.533955 | F4: =AVERAGEIF('Quarterly Performance'!$L$3:$L$1146, 1, 'Quarterly Performance'!G$3:G$1146) -> 28.366439 | G4: =AVERAGEIF('Quarterly Performance'!$L$3:$L$1146, 1, 'Quarterly Performance'!H$3:H$1146) -> 163.83277 | H4: =AVERAGEIF('Quarterly Performance'!$L$3:$L$1146, 1, 'Quarterly Performance'!I$3:I$1146) -> 52.236415 | I4: =IF(E4 <Percentiles!$E$3, "Low", IF(E4 <= Percentiles!$E$4, "Medium", "High")) -> High | J4: =IF(B4 <Percentiles!B$3, "Low", IF(B4 <= Percentiles!B$4, "Medium", "High")) -> Medium | K4: =IF(C4 <Percentiles!C$3, "Low", IF(C4 <= Percentiles!C$4, "Medium", "High")) -> Medium | L4: =IF(D4 <Percentiles!D$3, "Low", IF(D4 <= Percentiles!D$4, "Medium", "High")) -> Medium | M4: =IF(H4 <Percentiles!$H$3, "Low", IF(H4 <= Percentiles!$H$4, "Medium", "High")) -> Medium | N4: =(F4 - AVERAGE(F$2:$F$70)) / _xlfn.STDEV.S(F$2:F$70) -> -0.66239433 | O4: =(G4 - AVERAGE($G$2:G$70)) / _xlfn.STDEV.S(G$2:G$70) -> 0.99684076 | P4: =IF(AND(N4>=0, O4>=0), "Star", IF(AND(N4>=0, O4<0), "Cash Cow", IF(AND(N4<0, O4>=0), "Question Mark", "Dog"))) -> Question Mark
A5: Atlas Community Bank | B5: =AVERAGEIF('Quarterly Performance'!M$3:M$1146, 1, 'Quarterly Performance'!C$3:C$1146) -> 2.5157565e+08 | C5: =AVERAGEIF('Quarterly Performance'!$M$3:$M$1146, 1, 'Quarterly Performance'!D$3:D$1146) -> 46237848 | D5: =AVERAGEIF('Quarterly Performance'!$M$3:$M$1146, 1, 'Quarterly Performance'!E$3:E$1146) -> 2.053378e+08 | E5: =AVERAGEIF('Quarterly Performance'!$M$3:$M$1146, 1, 'Quarterly Performance'!F$3:F$1146) -> 55.280781 | F5: =AVERAGEIF('Quarterly Performance'!$M$3:$M$1146, 1, 'Quarterly Performance'!G$3:G$1146) -> 27.628856 | G5: =AVERAGEIF('Quarterly Performance'!$M$3:$M$1146, 1, 'Quarterly Performance'!H$3:H$1146) -> 4.8065792 | H5: =AVERAGEIF('Quarterly Performance'!$M$3:$M$1146, 1, 'Quarterly Performance'!I$3:I$1146) -> 52.05988 | I5: =IF(E5 <Percentiles!$E$3, "Low", IF(E5 <= Percentiles!$E$4, "Medium", "High")) -> Low | J5: =IF(B5 <Percentiles!B$3, "Low", IF(B5 <= Percentiles!B$4, "Medium", "High")) -> Medium | K5: =IF(C5 <Percentiles!C$3, "Low", IF(C5 <= Percentiles!C$4, "Medium", "High")) -> Medium | L5: =IF(D5 <Percentiles!D$3, "Low", IF(D5 <= Percentiles!D$4, "Medium", "High")) -> Medium | M5: =IF(H5 <Percentiles!$H$3, "Low", IF(H5 <= Percentiles!$H$4, "Medium", "High")) -> Medium | N5: =(F5 - AVERAGE(F$2:$F$70)) / _xlfn.STDEV.S(F$2:F$70) -> -0.79038605 | O5: =(G5 - AVERAGE($G$2:G$70)) / _xlfn.STDEV.S(G$2:G$70) -> -1.8105152 | P5: =IF(AND(N5>=0, O5>=0), "Star", IF(AND(N5>=0, O5<0), "Cash Cow", IF(AND(N5<0, O5>=0), "Question Mark", "Dog"))) -> Dog
A6: Atlas Private Equity | B6: =AVERAGEIF('Quarterly Performance'!N$3:N$1146, 1, 'Quarterly Performance'!C$3:C$1146) -> 2.4696762e+08 | C6: =AVERAGEIF('Quarterly Performance'!$N$3:$N$1146, 1, 'Quarterly Performance'!D$3:D$1146) -> 41734835 | D6: =AVERAGEIF('Quarterly Performance'!$N$3:$N$1146, 1, 'Quarterly Performance'!E$3:E$1146) -> 2.0523278e+08 | E6: =AVERAGEIF('Quarterly Performance'!$N$3:$N$1146, 1, 'Quarterly Performance'!F$3:F$1146) -> 60.512612 | F6: =AVERAGEIF('Quarterly Performance'!$N$3:$N$1146, 1, 'Quarterly Performance'!G$3:G$1146) -> 39.852829 | G6: =AVERAGEIF('Quarterly Performance'!$N$3:$N$1146, 1, 'Quarterly Performance'!H$3:H$1146) -> 145.36089 | H6: =AVERAGEIF('Quarterly Performance'!$N$3:$N$1146, 1, 'Quarterly Performance'!I$3:I$1146) -> 52.683721 | I6: =IF(E6 <Percentiles!$E$3, "Low", IF(E6 <= Percentiles!$E$4, "Medium", "High")) -> Medium | J6: =IF(B6 <Percentiles!B$3, "Low", IF(B6 <= Percentiles!B$4, "Medium", "High")) -> Medium | K6: =IF(C6 <Percentiles!C$3, "Low", IF(C6 <= Percentiles!C$4, "Medium", "High")) -> Medium | L6: =IF(D6 <Percentiles!D$3, "Low", IF(D6 <= Percentiles!D$4, "Medium", "High")) -> Medium | M6: =IF(H6 <Percentiles!$H$3, "Low", IF(H6 <= Percentiles!$H$4, "Medium", "High")) -> High | N6: =(F6 - AVERAGE(F$2:$F$70)) / _xlfn.STDEV.S(F$2:F$70) -> 1.3308246 | O6: =(G6 - AVERAGE($G$2:G$70)) / _xlfn.STDEV.S(G$2:G$70) -> 0.67074891 | P6: =IF(AND(N6>=0, O6>=0), "Star", IF(AND(N6>=0, O6<0), "Cash Cow", IF(AND(N6<0, O6>=0), "Question Mark", "Dog"))) -> Star
A7: Atlas Risk Management | B7: =AVERAGEIF('Quarterly Performance'!O$3:O$1146, 1, 'Quarterly Performance'!C$3:C$1146) -> 2.5049353e+08 | C7: =AVERAGEIF('Quarterly Performance'!$O$3:$O$1146, 1, 'Quarterly Performance'!D$3:D$1146) -> 46244964 | D7: =AVERAGEIF('Quarterly Performance'!$O$3:$O$1146, 1, 'Quarterly Performance'!E$3:E$1146) -> 2.0424857e+08 | E7: =AVERAGEIF('Quarterly Performance'!$O$3:$O$1146, 1, 'Quarterly Performance'!F$3:F$1146) -> 61.525078 | F7: =AVERAGEIF('Quarterly Performance'!$O$3:$O$1146, 1, 'Quarterly Performance'!G$3:G$1146) -> 36.544603 | G7: =AVERAGEIF('Quarterly Performance'!$O$3:$O$1146, 1, 'Quarterly Performance'!H$3:H$1146) -> 24.092841 | H7: =AVERAGEIF('Quarterly Performance'!$O$3:$O$1146, 1, 'Quarterly Performance'!I$3:I$1146) -> 52.578622 | I7: =IF(E7 <Percentiles!$E$3, "Low", IF(E7 <= Percentiles!$E$4, "Medium", "High")) -> Medium | J7: =IF(B7 <Percentiles!B$3, "Low", IF(B7 <= Percentiles!B$4, "Medium", "High")) -> Medium | K7: =IF(C7 <Percentiles!C$3, "Low", IF(C7 <= Percentiles!C$4, "Medium", "High")) -> Medium | L7: =IF(D7 <Percentiles!D$3, "Low", IF(D7 <= Percentiles!D$4, "Medium", "High")) -> Medium | M7: =IF(H7 <Percentiles!$H$3, "Low", IF(H7 <= Percentiles!$H$4, "Medium", "High")) -> High | N7: =(F7 - AVERAGE(F$2:$F$70)) / _xlfn.STDEV.S(F$2:F$70) -> 0.75675233 | O7: =(G7 - AVERAGE($G$2:G$70)) / _xlfn.STDEV.S(G$2:G$70) -> -1.4700468 | P7: =IF(AND(N7>=0, O7>=0), "Star", IF(AND(N7>=0, O7<0), "Cash Cow", IF(AND(N7<0, O7>=0), "Question Mark", "Dog"))) -> Cash Cow
A8: BlueSky Banking Corp. | B8: =AVERAGEIF('Quarterly Performance'!P$3:P$1146, 1, 'Quarterly Performance'!C$3:C$1146) -> 2.52725e+08 | C8: =AVERAGEIF('Quarterly Performance'!$P$3:$P$1146, 1, 'Quarterly Performance'!D$3:D$1146) -> 55556578 | D8: =AVERAGEIF('Quarterly Performance'!$P$3:$P$1146, 1, 'Quarterly Performance'!E$3:E$1146) -> 1.9716842e+08 | E8: =AVERAGEIF('Quarterly Performance'!$P$3:$P$1146, 1, 'Quarterly Performance'!F$3:F$1146) -> 58.951712 | F8: =AVERAGEIF('Quarterly Performance'!$P$3:$P$1146, 1, 'Quarterly Performance'!G$3:G$1146) -> 31.214133 | G8: =AVERAGEIF('Quarterly Performance'!$P$3:$P$1146, 1, 'Quarterly Performance'!H$3:H$1146) -> 100.85232 | H8: =AVERAGEIF('Quarterly Performance'!$P$3:$P$1146, 1, 'Quarterly Performance'!I$3:I$1146) -> 53.070695 | I8: =IF(E8 <Percentiles!$E$3, "Low", IF(E8 <= Percentiles!$E$4, "Medium", "High")) -> Medium | J8: =IF(B8 <Percentiles!B$3, "Low", IF(B8 <= Percentiles!B$4, "Medium", "High")) -> High | K8: =IF(C8 <Percentiles!C$3, "Low", IF(C8 <= Percentiles!C$4, "Medium", "High")) -> High | L8: =IF(D8 <Percentiles!D$3, "Low", IF(D8 <= Percentiles!D$4, "Medium", "High")) -> Medium | M8: =IF(H8 <Percentiles!$H$3, "Low", IF(H8 <= Percentiles!$H$4, "Medium", "High")) -> High | N8: =(F8 - AVERAGE(F$2:$F$70)) / _xlfn.STDEV.S(F$2:F$70) -> -0.16823742 | O8: =(G8 - AVERAGE($G$2:G$70)) / _xlfn.STDEV.S(G$2:G$70) -> -0.11497955 | P8: =IF(AND(N8>=0, O8>=0), "Star", IF(AND(N8>=0, O8<0), "Cash Cow", IF(AND(N8<0, O8>=0), "Question Mark", "Dog"))) -> Dog
A9: BlueSky Mobile Payments | B9: =AVERAGEIF('Quarterly Performance'!Q$3:Q$1146, 1, 'Quarterly Performance'!C$3:C$1146) -> 2.4406333e+08 | C9: =AVERAGEIF('Quarterly Performance'!$Q$3:$Q$1146, 1, 'Quarterly Performance'!D$3:D$1146) -> 47120286 | D9: =AVERAGEIF('Quarterly Performance'!$Q$3:$Q$1146, 1, 'Quarterly Performance'!E$3:E$1146) -> 1.9694305e+08 | E9: =AVERAGEIF('Quarterly Performance'!$Q$3:$Q$1146, 1, 'Quarterly Performance'!F$3:F$1146) -> 63.472889 | F9: =AVERAGEIF('Quarterly Performance'!$Q$3:$Q$1146, 1, 'Quarterly Performance'!G$3:G$1146) -> 24.630623 | G9: =AVERAGEIF('Quarterly Performance'!$Q$3:$Q$1146, 1, 'Quarterly Performance'!H$3:H$1146) -> 158.81829 | H9: =AVERAGEIF('Quarterly Performance'!$Q$3:$Q$1146, 1, 'Quarterly Performance'!I$3:I$1146) -> 52.835914 | I9: =IF(E9 <Percentiles!$E$3, "Low", IF(E9 <= Percentiles!$E$4, "Medium", "High")) -> Medium | J9: =IF(B9 <Percentiles!B$3, "Low", IF(B9 <= Percentiles!B$4, "Medium", "High")) -> Low | K9: =IF(C9 <Percentiles!C$3, "Low", IF(C9 <= Percentiles!C$4, "Medium", "High")) -> Medium | L9: =IF(D9 <Percentiles!D$3, "Low", IF(D9 <= Percentiles!D$4, "Medium", "High")) -> Medium | M9: =IF(H9 <Percentiles!$H$3, "Low", IF(H9 <= Percentiles!$H$4, "Medium", "High")) -> High | N9: =(F9 - AVERAGE(F$2:$F$70)) / _xlfn.STDEV.S(F$2:F$70) -> -1.3106656 | O9: =(G9 - AVERAGE($G$2:G$70)) / _xlfn.STDEV.S(G$2:G$70) -> 0.90831797 | P9: =IF(AND(N9>=0, O9>=0), "Star", IF(AND(N9>=0, O9<0), "Cash Cow", IF(AND(N9<0, O9>=0), "Question Mark", "Dog"))) -> Question Mark
A10: BlueSky Risk Solutions | B10: =AVERAGEIF('Quarterly Performance'!R$3:R$1146, 1, 'Quarterly Performance'!C$3:C$1146) -> 2.5891494e+08 | C10: =AVERAGEIF('Quarterly Performance'!$R$3:$R$1146, 1, 'Quarterly Performance'!D$3:D$1146) -> 43242243 | D10: =AVERAGEIF('Quarterly Performance'!$R$3:$R$1146, 1, 'Quarterly Performance'!E$3:E$1146) -> 2.1567269e+08 | E10: =AVERAGEIF('Quarterly Performance'!$R$3:$R$1146, 1, 'Quarterly Performance'!F$3:F$1146) -> 56.004864 | F10: =AVERAGEIF('Quarterly Performance'!$R$3:$R$1146, 1, 'Quarterly Performance'!G$3:G$1146) -> 30.810871 | G10: =AVERAGEIF('Quarterly Performance'!$R$3:$R$1146, 1, 'Quarterly Performance'!H$3:H$1146) -> 156.96239 | H10: =AVERAGEIF('Quarterly Performance'!$R$3:$R$1146, 1, 'Quarterly Performance'!I$3:I$1146) -> 54.117774 | I10: =IF(E10 <Percentiles!$E$3, "Low", IF(E10 <= Percentiles!$E$4, "Medium", "High")) -> Medium | J10: =IF(B10 <Percentiles!B$3, "Low", IF(B10 <= Percentiles!B$4, "Medium", "High")) -> High | K10: =IF(C10 <Percentiles!C$3, "Low", IF(C10 <= Percentiles!C$4, "Medium", "High")) -> Medium | L10: =IF(D10 <Percentiles!D$3, "Low", IF(D10 <= Percentiles!D$4, "Medium", "High")) -> High | M10: =IF(H10 <Percentiles!$H$3, "Low", IF(H10 <= Percentiles!$H$4, "Medium", "High")) -> High | N10: =(F10 - AVERAGE(F$2:$F$70)) / _xlfn.STDEV.S(F$2:F$70) -> -0.23821498 | O10: =(G10 - AVERAGE($G$2:G$70)) / _xlfn.STDEV.S(G$2:G$70) -> 0.87555507 | P10: =IF(AND(N10>=0, O10>=0), "Star", IF(AND(N10>=0, O10<0), "Cash Cow", IF(AND(N10<0, O10>=0), "Question Mark", "Dog"))) -> Question Mark
A11: CrestPoint Blockchain Solutions | B11: =AVERAGEIF('Quarterly Performance'!S$3:S$1146, 1, 'Quarterly Performance'!C$3:C$1146) -> 2.4843118e+08 | C11: =AVERAGEIF('Quarterly Performance'!$S$3:$S$1146, 1, 'Quarterly Performance'!D$3:D$1146) -> 55881504 | D11: =AVERAGEIF('Quarterly Performance'!$S$3:$S$1146, 1, 'Quarterly Performance'!E$3:E$1146) -> 1.9254967e+08 | E11: =AVERAGEIF('Quarterly Performance'!$S$3:$S$1146, 1, 'Quarterly Performance'!F$3:F$1146) -> 60.19932 | F11: =AVERAGEIF('Quarterly Performance'!$S$3:$S$1146, 1, 'Quarterly Performance'!G$3:G$1146) -> 27.067216 | G11: =AVERAGEIF('Quarterly Performance'!$S$3:$S$1146, 1, 'Quarterly Performance'!H$3:H$1146) -> 114.15672 | H11: =AVERAGEIF('Quarterly Performance'!$S$3:$S$1146, 1, 'Quarterly Performance'!I$3:I$1146) -> 51.189084 | I11: =IF(E11 <Percentiles!$E$3, "Low", IF(E11 <= Percentiles!$E$4, "Medium", "High")) -> Medium | J11: =IF(B11 <Percentiles!B$3, "Low", IF(B11 <= Percentiles!B$4, "Medium", "High")) -> Medium | K11: =IF(C11 <Percentiles!C$3, "Low", IF(C11 <= Percentiles!C$4, "Medium", "High")) -> High | L11: =IF(D11 <Percentiles!D$3, "Low", IF(D11 <= Percentiles!D$4, "Medium", "High")) -> Low | M11: =IF(H11 <Percentiles!$H$3, "Low", IF(H11 <= Percentiles!$H$4, "Medium", "High")) -> Medium | N11: =(F11 - AVERAGE(F$2:$F$70)) / _xlfn.STDEV.S(F$2:F$70) -> -0.88784678 | O11: =(G11 - AVERAGE($G$2:G$70)) / _xlfn.STDEV.S(G$2:G$70) -> 0.11988857 | P11: =IF(AND(N11>=0, O11>=0), "Star", IF(AND(N11>=0, O11<0), "Cash Cow", IF(AND(N11<0, O11>=0), "Question Mark", "Dog"))) -> Question Mark
A12: CrestPoint Capital | B12: =AVERAGEIF('Quarterly Performance'!T$3:T$1146, 1, 'Quarterly Performance'!C$3:C$1146) -> 2.5510177e+08 | C12: =AVERAGEIF('Quarterly Performance'!$T$3:$T$1146, 1, 'Quarterly Performance'!D$3:D$1146) -> 56491063 | D12: =AVERAGEIF('Quarterly Performance'!$T$3:$T$1146, 1, 'Quarterly Performance'!E$3:E$1146) -> 1.9861071e+08 | E12: =AVERAGEIF('Quarterly Performance'!$T$3:$T$1146, 1, 'Quarterly Performance'!F$3:F$1146) -> 55.260188 | F12: =AVERAGEIF('Quarterly Performance'!$T$3:$T$1146, 1, 'Quarterly Performance'!G$3:G$1146) -> 28.209216 | G12: =AVERAGEIF('Quarterly Performance'!$T$3:$T$1146, 1, 'Quarterly Performance'!H$3:H$1146) -> 83.223643 | H12: =AVERAGEIF('Quarterly Performance'!$T$3:$T$1146, 1, 'Quarterly Performance'!I$3:I$1146) -> 51.978358 | I12: =IF(E12 <Percentiles!$E$3, "Low", IF(E12 <= Percentiles!$E$4, "Medium", "High")) -> Low | J12: =IF(B12 <Percentiles!B$3, "Low", IF(B12 <= Percentiles!B$4, "Medium", "High")) -> High | K12: =IF(C12 <Percentiles!C$3, "Low", IF(C12 <= Percentiles!C$4, "Medium", "High")) -> High | L12: =IF(D12 <Percentiles!D$3, "Low", IF(D12 <= Percentiles!D$4, "Medium", "High")) -> Medium | M12: =IF(H12 <Percentiles!$H$3, "Low", IF(H12 <= Percentiles!$H$4, "Medium", "High")) -> Medium | N12: =(F12 - AVERAGE(F$2:$F$70)) / _xlfn.STDEV.S(F$2:F$70) -> -0.68967698 | O12: =(G12 - AVERAGE($G$2:G$70)) / _xlfn.STDEV.S(G$2:G$70) -> -0.42618595 | P12: =IF(AND(N12>=0, O12>=0), "Star", IF(AND(N12>=0, O12<0), "Cash Cow", IF(AND(N12<0, O12>=0), "Question Mark", "Dog"))) -> Dog
A13: CryptoBridge Systems | B13: =AVERAGEIF('Quarterly Performance'!U$3:U$1146, 1, 'Quarterly Performance'!C$3:C$1146) -> 2.5165992e+08 | C13: =AVERAGEIF('Quarterly Performance'!$U$3:$U$1146, 1, 'Quarterly Performance'!D$3:D$1146) -> 48156530 | D13: =AVERAGEIF('Quarterly Performance'!$U$3:$U$1146, 1, 'Quarterly Performance'!E$3:E$1146) -> 2.0350339e+08 | E13: =AVERAGEIF('Quarterly Performance'!$U$3:$U$1146, 1, 'Quarterly Performance'!F$3:F$1146) -> 68.115829 | F13: =AVERAGEIF('Quarterly Performance'!$U$3:$U$1146, 1, 'Quarterly Performance'!G$3:G$1146) -> 35.884402 | G13: =AVERAGEIF('Quarterly Performance'!$U$3:$U$1146, 1, 'Quarterly Performance'!H$3:H$1146) -> 104.39582 | H13: =AVERAGEIF('Quarterly Performance'!$U$3:$U$1146, 1, 'Quarterly Performance'!I$3:I$1146) -> 53.165772 | I13: =IF(E13 <Percentiles!$E$3, "Low", IF(E13 <= Percentiles!$E$4, "Medium", "High")) -> High | J13: =IF(B13 <Percentiles!B$3, "Low", IF(B13 <= Percentiles!B$4, "Medium", "High")) -> Medium | K13: =IF(C13 <Percentiles!C$3, "Low", IF(C13 <= Percentiles!C$4, "Medium", "High")) -> Medium | L13: =IF(D13 <Percentiles!D$3, "Low", IF(D13 <= Percentiles!D$4, "Medium", "High")) -> Medium | M13: =IF(H13 <Percentiles!$H$3, "Low", IF(H13 <= Percentiles!$H$4, "Medium", "High")) -> High | N13: =(F13 - AVERAGE(F$2:$F$70)) / _xlfn.STDEV.S(F$2:F$70) -> 0.64218841 | O13: =(G13 - AVERAGE($G$2:G$70)) / _xlfn.STDEV.S(G$2:G$70) -> -0.05242465 | P13: =IF(AND(N13>=0, O13>=0), "Star", IF(AND(N13>=0, O13<0), "Cash Cow", IF(AND(N13<0, O13>=0), "Question Mark", "Dog"))) -> Cash Cow
A14: Evergreen Coverage Co. | B14: =AVERAGEIF('Quarterly Performance'!V$3:V$1146, 1, 'Quarterly Performance'!C$3:C$1146) -> 2.4663916e+08 | C14: =AVERAGEIF('Quarterly Performance'!$V$3:$V$1146, 1, 'Quarterly Performance'!D$3:D$1146) -> 55656821 | D14: =AVERAGEIF('Quarterly Performance'!$V$3:$V$1146, 1, 'Quarterly Performance'!E$3:E$1146) -> 1.9098234e+08 | E14: =AVERAGEIF('Quarterly Performance'!$V$3:$V$1146, 1, 'Quarterly Performance'!F$3:F$1146) -> 59.874227 | F14: =AVERAGEIF('Quarterly Performance'!$V$3:$V$1146, 1, 'Quarterly Performance'!G$3:G$1146) -> 27.261187 | G14: =AVERAGEIF('Quarterly Performance'!$V$3:$V$1146, 1, 'Quarterly Performance'!H$3:H$1146) -> 224.93924 | H14: =AVERAGEIF('Quarterly Performance'!$V$3:$V$1146, 1, 'Quarterly Performance'!I$3:I$1146) -> 49.114182 | I14: =IF(E14 <Percentiles!$E$3, "Low", IF(E14 <= Percentiles!$E$4, "Medium", "High")) -> Medium | J14: =IF(B14 <Percentiles!B$3, "Low", IF(B14 <= Percentiles!B$4, "Medium", "High")) -> Medium | K14: =IF(C14 <Percentiles!C$3, "Low", IF(C14 <= Percentiles!C$4, "Medium", "High")) -> High | L14: =IF(D14 <Percentiles!D$3, "Low", IF(D14 <= Percentiles!D$4, "Medium", "High")) -> Low | M14: =IF(H14 <Percentiles!$H$3, "Low", IF(H14 <= Percentiles!$H$4, "Medium", "High")) -> Medium | N14: =(F14 - AVERAGE(F$2:$F$70)) / _xlfn.STDEV.S(F$2:F$70) -> -0.85418727 | O14: =(G14 - AVERAGE($G$2:G$70)) / _xlfn.STDEV.S(G$2:G$70) -> 2.0755788 | P14: =IF(AND(N14>=0, O14>=0), "Star", IF(AND(N14>=0, O14<0), "Cash Cow", IF(AND(N14<0, O14>=0), "Question Mark", "Dog"))) -> Question Mark
A15: Evergreen Depository Services | B15: =AVERAGEIF('Quarterly Performance'!W$3:W$1146, 1, 'Quarterly Performance'!C$3:C$1146) -> 2.4507366e+08 | C15: =AVERAGEIF('Quarterly Performance'!$W$3:$W$1146, 1, 'Quarterly Performance'!D$3:D$1146) -> 40612044 | D15: =AVERAGEIF('Quarterly Performance'!$W$3:$W$1146, 1, 'Quarterly Performance'!E$3:E$1146) -> 2.0446162e+08 | E15: =AVERAGEIF('Quarterly Performance'!$W$3:$W$1146, 1, 'Quarterly Performance'!F$3:F$1146) -> 55.901821 | F15: =AVERAGEIF('Quarterly Performance'!$W$3:$W$1146, 1, 'Quarterly Performance'!G$3:G$1146) -> 34.889367 | G15: =AVERAGEIF('Quarterly Performance'!$W$3:$W$1146, 1, 'Quarterly Performance'!H$3:H$1146) -> 91.224128 | H15: =AVERAGEIF('Quarterly Performance'!$W$3:$W$1146, 1, 'Quarterly Performance'!I$3:I$1146) -> 48.879208 | I15: =IF(E15 <Percentiles!$E$3, "Low", IF(E15 <= Percentiles!$E$4, "Medium", "High")) -> Medium | J15: =IF(B15 <Percentiles!B$3, "Low", IF(B15 <= Percentiles!B$4, "Medium", "High")) -> Low | K15: =IF(C15 <Percentiles!C$3, "Low", IF(C15 <= Percentiles!C$4, "Medium", "High")) -> Low | L15: =IF(D15 <Percentiles!D$3, "Low", IF(D15 <= Percentiles!D$4, "Medium", "High")) -> Medium | M15: =IF(H15 <Percentiles!$H$3, "Low", IF(H15 <= Percentiles!$H$4, "Medium", "High")) -> Medium | N15: =(F15 - AVERAGE(F$2:$F$70)) / _xlfn.STDEV.S(F$2:F$70) -> 0.46952129 | O15: =(G15 - AVERAGE($G$2:G$70)) / _xlfn.STDEV.S(G$2:G$70) -> -0.28495003 | P15: =IF(AND(N15>=0, O15>=0), "Star", IF(AND(N15>=0, O15<0), "Cash Cow", IF(AND(N15<0, O15>=0), "Question Mark", "Dog"))) -> Cash Cow
A16: Evergreen Equity Group | B16: =AVERAGEIF('Quarterly Performance'!X$3:X$1146, 1, 'Quarterly Performance'!C$3:C$1146) -> 2.5820677e+08 | C16: =AVERAGEIF('Quarterly Performance'!$X$3:$X$1146, 1, 'Quarterly Performance'!D$3:D$1146) -> 38149610 | D16: =AVERAGEIF('Quarterly Performance'!$X$3:$X$1146, 1, 'Quarterly Performance'!E$3:E$1146) -> 2.2005716e+08 | E16: =AVERAGEIF('Quarterly Performance'!$X$3:$X$1146, 1, 'Quarterly Performance'!F$3:F$1146) -> 60.245896 | F16: =AVERAGEIF('Quarterly Performance'!$X$3:$X$1146, 1, 'Quarterly Performance'!G$3:G$1146) -> 25.647622 | G16: =AVERAGEIF('Quarterly Performance'!$X$3:$X$1146, 1, 'Quarterly Performance'!H$3:H$1146) -> 104.18933 | H16: =AVERAGEIF('Quarterly Performance'!$X$3:$X$1146, 1, 'Quarterly Performance'!I$3:I$1146) -> 50.914046 | I16: =IF(E16 <Percentiles!$E$3, "Low", IF(E16 <= Percentiles!$E$4, "Medium", "High")) -> Medium | J16: =IF(B16 <Percentiles!B$3, "Low", IF(B16 <= Percentiles!B$4, "Medium", "High")) -> High | K16: =IF(C16 <Percentiles!C$3, "Low", IF(C16 <= Percentiles!C$4, "Medium", "High")) -> Low | L16: =IF(D16 <Percentiles!D$3, "Low", IF(D16 <= Percentiles!D$4, "Medium", "High")) -> High | M16: =IF(H16 <Percentiles!$H$3, "Low", IF(H16 <= Percentiles!$H$4, "Medium", "High")) -> Medium | N16: =(F16 - AVERAGE(F$2:$F$70)) / _xlfn.STDEV.S(F$2:F$70) -> -1.1341872 | O16: =(G16 - AVERAGE($G$2:G$70)) / _xlfn.STDEV.S(G$2:G$70) -> -0.056069961 | P16: =IF(AND(N16>=0, O16>=0), "Star", IF(AND(N16>=0, O16<0), "Cash Cow", IF(AND(N16<0, O16>=0), "Question Mark", "Dog"))) -> Dog
A17: Evergreen FinTech Group | B17: =AVERAGEIF('Quarterly Performance'!Y$3:Y$1146, 1, 'Quarterly Performance'!C$3:C$1146) -> 2.4964782e+08 | C17: =AVERAGEIF('Quarterly Performance'!$Y$3:$Y$1146, 1, 'Quarterly Performance'!D$3:D$1146) -> 50183039 | D17: =AVERAGEIF('Quarterly Performance'!$Y$3:$Y$1146, 1, 'Quarterly Performance'!E$3:E$1146) -> 1.9946478e+08 | E17: =AVERAGEIF('Quarterly Performance'!$Y$3:$Y$1146, 1, 'Quarterly Performance'!F$3:F$1146) -> 53.665232 | F17: =AVERAGEIF('Quarterly Performance'!$Y$3:$Y$1146, 1, 'Quarterly Performance'!G$3:G$1146) -> 25.462883 | G17: =AVERAGEIF('Quarterly Performance'!$Y$3:$Y$1146, 1, 'Quarterly Performance'!H$3:H$1146) -> 83.994721 | H17: =AVERAGEIF('Quarterly Performance'!$Y$3:$Y$1146, 1, 'Quarterly Performance'!I$3:I$1146) -> 49.532884 | I17: =IF(E17 <Percentiles!$E$3, "Low", IF(E17 <= Percentiles!$E$4, "Medium", "High")) -> Low | J17: =IF(B17 <Percentiles!B$3, "Low", IF(B17 <= Percentiles!B$4, "Medium", "High")) -> Medium | K17: =IF(C17 <Percentiles!C$3, "Low", IF(C17 <= Percentiles!C$4, "Medium", "High")) -> Medium | L17: =IF(D17 <Percentiles!D$3, "Low", IF(D17 <= Percentiles!D$4, "Medium", "High")) -> Medium | M17: =IF(H17 <Percentiles!$H$3, "Low", IF(H17 <= Percentiles!$H$4, "Medium", "High")) -> Medium | N17: =(F17 - AVERAGE(F$2:$F$70)) / _xlfn.STDEV.S(F$2:F$70) -> -1.1662447 | O17: =(G17 - AVERAGE($G$2:G$70)) / _xlfn.STDEV.S(G$2:G$70) -> -0.41257378 | P17: =IF(AND(N17>=0, O17>=0), "Star", IF(AND(N17>=0, O17<0), "Cash Cow", IF(AND(N17<0, O17>=0), "Question Mark", "Dog"))) -> Dog
A18: Golden Gate Depository | B18: =AVERAGEIF('Quarterly Performance'!Z$3:Z$1146, 1, 'Quarterly Performance'!C$3:C$1146) -> 2.5315191e+08 | C18: =AVERAGEIF('Quarterly Performance'!$Z$3:$Z$1146, 1, 'Quarterly Performance'!D$3:D$1146) -> 28892596 | D18: =AVERAGEIF('Quarterly Performance'!$Z$3:$Z$1146, 1, 'Quarterly Performance'!E$3:E$1146) -> 2.2425932e+08 | E18: =AVERAGEIF('Quarterly Performance'!$Z$3:$Z$1146, 1, 'Quarterly Performance'!F$3:F$1146) -> 62.333471 | F18: =AVERAGEIF('Quarterly Performance'!$Z$3:$Z$1146, 1, 'Quarterly Performance'!G$3:G$1146) -> 26.656375 | G18: =AVERAGEIF('Quarterly Performance'!$Z$3:$Z$1146, 1, 'Quarterly Performance'!H$3:H$1146) -> 131.66862 | H18: =AVERAGEIF('Quarterly Performance'!$Z$3:$Z$1146, 1, 'Quarterly Performance'!I$3:I$1146) -> 47.322868 | I18: =IF(E18 <Percentiles!$E$3, "Low", IF(E18 <= Percentiles!$E$4, "Medium", "High")) -> Medium | J18: =IF(B18 <Percentiles!B$3, "Low", IF(B18 <= Percentiles!B$4, "Medium", "High")) -> High | K18: =IF(C18 <Percentiles!C$3, "Low", IF(C18 <= Percentiles!C$4, "Medium", "High")) -> Low | L18: =IF(D18 <Percentiles!D$3, "Low", IF(D18 <= Percentiles!D$4, "Medium", "High")) -> High | M18: =IF(H18 <Percentiles!$H$3, "Low", IF(H18 <= Percentiles!$H$4, "Medium", "High")) -> Low | N18: =(F18 - AVERAGE(F$2:$F$70)) / _xlfn.STDEV.S(F$2:F$70) -> -0.95913945 | O18: =(G18 - AVERAGE($G$2:G$70)) / _xlfn.STDEV.S(G$2:G$70) -> 0.42903348 | P18: =IF(AND(N18>=0, O18>=0), "Star", IF(AND(N18>=0, O18<0), "Cash Cow", IF(AND(N18<0, O18>=0), "Question Mark", "Dog"))) -> Question Mark
A19: Golden Gate Digital Finance | B19: =AVERAGEIF('Quarterly Performance'!AA$3:AA$1146, 1, 'Quarterly Performance'!C$3:C$1146) -> 2.5041025e+08 | C19: =AVERAGEIF('Quarterly Performance'!$AA$3:$AA$1146, 1, 'Quarterly Performance'!D$3:D$1146) -> 47991137 | D19: =AVERAGEIF('Quarterly Performance'!$AA$3:$AA$1146, 1, 'Quarterly Performance'!E$3:E$1146) -> 2.0241911e+08 | E19: =AVERAGEIF('Quarterly Performance'!$AA$3:$AA$1146, 1, 'Quarterly Performance'!F$3:F$1146) -> 64.994594 | F19: =AVERAGEIF('Quarterly Performance'!$AA$3:$AA$1146, 1, 'Quarterly Performance'!G$3:G$1146) -> 44.525106 | G19: =AVERAGEIF('Quarterly Performance'!$AA$3:$AA$1146, 1, 'Quarterly Performance'!H$3:H$1146) -> 73.050206 | H19: =AVERAGEIF('Quarterly Performance'!$AA$3:$AA$1146, 1, 'Quarterly Performance'!I$3:I$1146) -> 49.877328 | I19: =IF(E19 <Percentiles!$E$3, "Low", IF(E19 <= Percentiles!$E$4, "Medium", "High")) -> High | J19: =IF(B19 <Percentiles!B$3, "Low", IF(B19 <= Percentiles!B$4, "Medium", "High")) -> Medium | K19: =IF(C19 <Percentiles!C$3, "Low", IF(C19 <= Percentiles!C$4, "Medium", "High")) -> Medium | L19: =IF(D19 <Percentiles!D$3, "Low", IF(D19 <= Percentiles!D$4, "Medium", "High")) -> Medium | M19: =IF(H19 <Percentiles!$H$3, "Low", IF(H19 <= Percentiles!$H$4, "Medium", "High")) -> Medium | N19: =(F19 - AVERAGE(F$2:$F$70)) / _xlfn.STDEV.S(F$2:F$70) -> 2.141599 | O19: =(G19 - AVERAGE($G$2:G$70)) / _xlfn.STDEV.S(G$2:G$70) -> -0.60578189 | P19: =IF(AND(N19>=0, O19>=0), "Star", IF(AND(N19>=0, O19<0), "Cash Cow", IF(AND(N19<0, O19>=0), "Question Mark", "Dog"))) -> Cash Cow
A20: Golden Gate Insurance Partners | B20: =AVERAGEIF('Quarterly Performance'!AB$3:AB$1146, 1, 'Quarterly Performance'!C$3:C$1146) -> 2.4706455e+08 | C20: =AVERAGEIF('Quarterly Performance'!$AB$3:$AB$1146, 1, 'Quarterly Performance'!D$3:D$1146) -> 37664376 | D20: =AVERAGEIF('Quarterly Performance'!$AB$3:$AB$1146, 1, 'Quarterly Performance'!E$3:E$1146) -> 2.0940017e+08 | E20: =AVERAGEIF('Quarterly Performance'!$AB$3:$AB$1146, 1, 'Quarterly Performance'!F$3:F$1146) -> 55.486538 | F20: =AVERAGEIF('Quarterly Performance'!$AB$3:$AB$1146, 1, 'Quarterly Performance'!G$3:G$1146) -> 39.606641 | G20: =AVERAGEIF('Quarterly Performance'!$AB$3:$AB$1146, 1, 'Quarterly Performance'!H$3:H$1146) -> 74.1652 | H20: =AVERAGEIF('Quarterly Performance'!$AB$3:$AB$1146, 1, 'Quarterly Performance'!I$3:I$1146) -> 47.40751 | I20: =IF(E20 <Percentiles!$E$3, "Low", IF(E20 <= Percentiles!$E$4, "Medium", "High")) -> Low | J20: =IF(B20 <Percentiles!B$3, "Low", IF(B20 <= Percentiles!B$4, "Medium", "High")) -> Medium | K20: =IF(C20 <Percentiles!C$3, "Low", IF(C20 <= Percentiles!C$4, "Medium", "High")) -> Low | L20: =IF(D20 <Percentiles!D$3, "Low", IF(D20 <= Percentiles!D$4, "Medium", "High")) -> High | M20: =IF(H20 <Percentiles!$H$3, "Low", IF(H20 <= Percentiles!$H$4, "Medium", "High")) -> Low | N20: =(F20 - AVERAGE(F$2:$F$70)) / _xlfn.STDEV.S(F$2:F$70) -> 1.2881038 | O20: =(G20 - AVERAGE($G$2:G$70)) / _xlfn.STDEV.S(G$2:G$70) -> -0.58609844 | P20: =IF(AND(N20>=0, O20>=0), "Star", IF(AND(N20>=0, O20<0), "Cash Cow", IF(AND(N20<0, O20>=0), "Question Mark", "Dog"))) -> Cash Cow
A21: Granite State Credit Union | B21: =AVERAGEIF('Quarterly Performance'!AC$3:AC$1146, 1, 'Quarterly Performance'!C$3:C$1146) -> 2.4463677e+08 | C21: =AVERAGEIF('Quarterly Performance'!$AC$3:$AC$1146, 1, 'Quarterly Performance'!D$3:D$1146) -> 42853953 | D21: =AVERAGEIF('Quarterly Performance'!$AC$3:$AC$1146, 1, 'Quarterly Performance'!E$3:E$1146) -> 2.0178281e+08 | E21: =AVERAGEIF('Quarterly Performance'!$AC$3:$AC$1146, 1, 'Quarterly Performance'!F$3:F$1146) -> 53.730777 | F21: =AVERAGEIF('Quarterly Performance'!$AC$3:$AC$1146, 1, 'Quarterly Performance'!G$3:G$1146) -> 35.218058 | G21: =AVERAGEIF('Quarterly Performance'!$AC$3:$AC$1146, 1, 'Quarterly Performance'!H$3:H$1146) -> 108.95306 | H21: =AVERAGEIF('Quarterly Performance'!$AC$3:$AC$1146, 1, 'Quarterly Performance'!I$3:I$1146) -> 48.493704 | I21: =IF(E21 <Percentiles!$E$3, "Low", IF(E21 <= Percentiles!$E$4, "Medium", "High")) -> Low | J21: =IF(B21 <Percentiles!B$3, "Low", IF(B21 <= Percentiles!B$4, "Medium", "High")) -> Low | K21: =IF(C21 <Percentiles!C$3, "Low", IF(C21 <= Percentiles!C$4, "Medium", "High")) -> Medium | L21: =IF(D21 <Percentiles!D$3, "Low", IF(D21 <= Percentiles!D$4, "Medium", "High")) -> Medium | M21: =IF(H21 <Percentiles!$H$3, "Low", IF(H21 <= Percentiles!$H$4, "Medium", "High")) -> Medium | N21: =(F21 - AVERAGE(F$2:$F$70)) / _xlfn.STDEV.S(F$2:F$70) -> 0.52655858 | O21: =(G21 - AVERAGE($G$2:G$70)) / _xlfn.STDEV.S(G$2:G$70) -> 0.028026151 | P21: =IF(AND(N21>=0, O21>=0), "Star", IF(AND(N21>=0, O21<0), "Cash Cow", IF(AND(N21<0, O21>=0), "Question Mark", "Dog"))) -> Star
A22: Guardian Life Assurance | B22: =AVERAGEIF('Quarterly Performance'!AD$3:AD$1146, 1, 'Quarterly Performance'!C$3:C$1146) -> 2.4765086e+08 | C22: =AVERAGEIF('Quarterly Performance'!$AD$3:$AD$1146, 1, 'Quarterly Performance'!D$3:D$1146) -> 51363347 | D22: =AVERAGEIF('Quarterly Performance'!$AD$3:$AD$1146, 1, 'Quarterly Performance'!E$3:E$1146) -> 1.9628751e+08 | E22: =AVERAGEIF('Quarterly Performance'!$AD$3:$AD$1146, 1, 'Quarterly Performance'!F$3:F$1146) -> 51.069611 | F22: =AVERAGEIF('Quarterly Performance'!$AD$3:$AD$1146, 1, 'Quarterly Performance'!G$3:G$1146) -> 22.3705 | G22: =AVERAGEIF('Quarterly Performance'!$AD$3:$AD$1146, 1, 'Quarterly Performance'!H$3:H$1146) -> 102.69472 | H22: =AVERAGEIF('Quarterly Performance'!$AD$3:$AD$1146, 1, 'Quarterly Performance'!I$3:I$1146) -> 48.935889 | I22: =IF(E22 <Percentiles!$E$3, "Low", IF(E22 <= Percentiles!$E$4, "Medium", "High")) -> Low | J22: =IF(B22 <Percentiles!B$3, "Low", IF(B22 <= Percentiles!B$4, "Medium", "High")) -> Medium | K22: =IF(C22 <Percentiles!C$3, "Low", IF(C22 <= Percentiles!C$4, "Medium", "High")) -> Medium | L22: =IF(D22 <Percentiles!D$3, "Low", IF(D22 <= Percentiles!D$4, "Medium", "High")) -> Medium | M22: =IF(H22 <Percentiles!$H$3, "Low", IF(H22 <= Percentiles!$H$4, "Medium", "High")) -> Medium | N22: =(F22 - AVERAGE(F$2:$F$70)) / _xlfn.STDEV.S(F$2:F$70) -> -1.7028621 | O22: =(G22 - AVERAGE($G$2:G$70)) / _xlfn.STDEV.S(G$2:G$70) -> -0.082454792 | P22: =IF(AND(N22>=0, O22>=0), "Star", IF(AND(N22>=0, O22<0), "Cash Cow", IF(AND(N22<0, O22>=0), "Question Mark", "Dog"))) -> Dog
A23: GuardianPay Tech | B23: =AVERAGEIF('Quarterly Performance'!AE$3:AE$1146, 1, 'Quarterly Performance'!C$3:C$1146) -> 2.5821169e+08 | C23: =AVERAGEIF('Quarterly Performance'!$AE$3:$AE$1146, 1, 'Quarterly Performance'!D$3:D$1146) -> 80218068 | D23: =AVERAGEIF('Quarterly Performance'!$AE$3:$AE$1146, 1, 'Quarterly Performance'!E$3:E$1146) -> 1.7799363e+08 | E23: =AVERAGEIF('Quarterly Performance'!$AE$3:$AE$1146, 1, 'Quarterly Performance'!F$3:F$1146) -> 65.016223 | F23: =AVERAGEIF('Quarterly Performance'!$AE$3:$AE$1146, 1, 'Quarterly Performance'!G$3:G$1146) -> 31.666886 | G23: =AVERAGEIF('Quarterly Performance'!$AE$3:$AE$1146, 1, 'Quarterly Performance'!H$3:H$1146) -> 208.71226 | H23: =AVERAGEIF('Quarterly Performance'!$AE$3:$AE$1146, 1, 'Quarterly Performance'!I$3:I$1146) -> 46.497151 | I23: =IF(E23 <Percentiles!$E$3, "Low", IF(E23 <= Percentiles!$E$4, "Medium", "High")) -> High | J23: =IF(B23 <Percentiles!B$3, "Low", IF(B23 <= Percentiles!B$4, "Medium", "High")) -> High | K23: =IF(C23 <Percentiles!C$3, "Low", IF(C23 <= Percentiles!C$4, "Medium", "High")) -> High | L23: =IF(D23 <Percentiles!D$3, "Low", IF(D23 <= Percentiles!D$4, "Medium", "High")) -> Low | M23: =IF(H23 <Percentiles!$H$3, "Low", IF(H23 <= Percentiles!$H$4, "Medium", "High")) -> Low | N23: =(F23 - AVERAGE(F$2:$F$70)) / _xlfn.STDEV.S(F$2:F$70) -> -0.089671827 | O23: =(G23 - AVERAGE($G$2:G$70)) / _xlfn.STDEV.S(G$2:G$70) -> 1.7891171 | P23: =IF(AND(N23>=0, O23>=0), "Star", IF(AND(N23>=0, O23<0), "Cash Cow", IF(AND(N23<0, O23>=0), "Question Mark", "Dog"))) -> Question Mark
A24: GuardianPay Technologies | B24: =AVERAGEIF('Quarterly Performance'!AF$3:AF$1146, 1, 'Quarterly Performance'!C$3:C$1146) -> 2.4544786e+08 | C24: =AVERAGEIF('Quarterly Performance'!$AF$3:$AF$1146, 1, 'Quarterly Performance'!D$3:D$1146) -> 43066719 | D24: =AVERAGEIF('Quarterly Performance'!$AF$3:$AF$1146, 1, 'Quarterly Performance'!E$3:E$1146) -> 2.0238114e+08 | E24: =AVERAGEIF('Quarterly Performance'!$AF$3:$AF$1146, 1, 'Quarterly Performance'!F$3:F$1146) -> 58.057929 | F24: =AVERAGEIF('Quarterly Performance'!$AF$3:$AF$1146, 1, 'Quarterly Performance'!G$3:G$1146) -> 36.779897 | G24: =AVERAGEIF('Quarterly Performance'!$AF$3:$AF$1146, 1, 'Quarterly Performance'!H$3:H$1146) -> 104.0531 | H24: =AVERAGEIF('Quarterly Performance'!$AF$3:$AF$1146, 1, 'Quarterly Performance'!I$3:I$1146) -> 48.91084 | I24: =IF(E24 <Percentiles!$E$3, "Low", IF(E24 <= Percentiles!$E$4, "Medium", "High")) -> Medium | J24: =IF(B24 <Percentiles!B$3, "Low", IF(B24 <= Percentiles!B$4, "Medium", "High")) -> Low | K24: =IF(C24 <Percentiles!C$3, "Low", IF(C24 <= Percentiles!C$4, "Medium", "High")) -> Medium | L24: =IF(D24 <Percentiles!D$3, "Low", IF(D24 <= Percentiles!D$4, "Medium", "High")) -> Medium | M24: =IF(H24 <Percentiles!$H$3, "Low", IF(H24 <= Percentiles!$H$4, "Medium", "High")) -> Medium | N24: =(F24 - AVERAGE(F$2:$F$70)) / _xlfn.STDEV.S(F$2:F$70) -> 0.79758249 | O24: =(G24 - AVERAGE($G$2:G$70)) / _xlfn.STDEV.S(G$2:G$70) -> -0.058474911 | P24: =IF(AND(N24>=0, O24>=0), "Star", IF(AND(N24>=0, O24<0), "Cash Cow", IF(AND(N24<0, O24>=0), "Question Mark", "Dog"))) -> Cash Cow
A25: Harborview Savings Bank | B25: =AVERAGEIF('Quarterly Performance'!AG$3:AG$1146, 1, 'Quarterly Performance'!C$3:C$1146) -> 2.3718942e+08 | C25: =AVERAGEIF('Quarterly Performance'!$AG$3:$AG$1146, 1, 'Quarterly Performance'!D$3:D$1146) -> 49490506 | D25: =AVERAGEIF('Quarterly Performance'!$AG$3:$AG$1146, 1, 'Quarterly Performance'!E$3:E$1146) -> 1.8769891e+08 | E25: =AVERAGEIF('Quarterly Performance'!$AG$3:$AG$1146, 1, 'Quarterly Performance'!F$3:F$1146) -> 49.469159 | F25: =AVERAGEIF('Quarterly Performance'!$AG$3:$AG$1146, 1, 'Quarterly Performance'!G$3:G$1146) -> 26.548031 | G25: =AVERAGEIF('Quarterly Performance'!$AG$3:$AG$1146, 1, 'Quarterly Performance'!H$3:H$1146) -> 4.2475682 | H25: =AVERAGEIF('Quarterly Performance'!$AG$3:$AG$1146, 1, 'Quarterly Performance'!I$3:I$1146) -> 48.62574 | I25: =IF(E25 <Percentiles!$E$3, "Low", IF(E25 <= Percentiles!$E$4, "Medium", "High")) -> Low | J25: =IF(B25 <Percentiles!B$3, "Low", IF(B25 <= Percentiles!B$4, "Medium", "High")) -> Low | K25: =IF(C25 <Percentiles!C$3, "Low", IF(C25 <= Percentiles!C$4, "Medium", "High")) -> Medium | L25: =IF(D25 <Percentiles!D$3, "Low", IF(D25 <= Percentiles!D$4, "Medium", "High")) -> Low | M25: =IF(H25 <Percentiles!$H$3, "Low", IF(H25 <= Percentiles!$H$4, "Medium", "High")) -> Medium | N25: =(F25 - AVERAGE(F$2:$F$70)) / _xlfn.STDEV.S(F$2:F$70) -> -0.97794031 | O25: =(G25 - AVERAGE($G$2:G$70)) / _xlfn.STDEV.S(G$2:G$70) -> -1.8203837 | P25: =IF(AND(N25>=0, O25>=0), "Star", IF(AND(N25>=0, O25<0), "Cash Cow", IF(AND(N25<0, O25>=0), "Question Mark", "Dog"))) -> Dog
A26: Horizon Health & Life | B26: =AVERAGEIF('Quarterly Performance'!AH$3:AH$1146, 1, 'Quarterly Performance'!C$3:C$1146) -> 2.4498817e+08 | C26: =AVERAGEIF('Quarterly Performance'!$AH$3:$AH$1146, 1, 'Quarterly Performance'!D$3:D$1146) -> 25675075 | D26: =AVERAGEIF('Quarterly Performance'!$AH$3:$AH$1146, 1, 'Quarterly Performance'!E$3:E$1146) -> 2.1931309e+08 | E26: =AVERAGEIF('Quarterly Performance'!$AH$3:$AH$1146, 1, 'Quarterly Performance'!F$3:F$1146) -> 67.536058 | F26: =AVERAGEIF('Quarterly Performance'!$AH$3:$AH$1146, 1, 'Quarterly Performance'!G$3:G$1146) -> 40.560265 | G26: =AVERAGEIF('Quarterly Performance'!$AH$3:$AH$1146, 1, 'Quarterly Performance'!H$3:H$1146) -> 48.383893 | H26: =AVERAGEIF('Quarterly Performance'!$AH$3:$AH$1146, 1, 'Quarterly Performance'!I$3:I$1146) -> 52.25087 | I26: =IF(E26 <Percentiles!$E$3, "Low", IF(E26 <= Percentiles!$E$4, "Medium", "High")) -> High | J26: =IF(B26 <Percentiles!B$3, "Low", IF(B26 <= Percentiles!B$4, "Medium", "High")) -> Low | K26: =IF(C26 <Percentiles!C$3, "Low", IF(C26 <= Percentiles!C$4, "Medium", "High")) -> Low | L26: =IF(D26 <Percentiles!D$3, "Low", IF(D26 <= Percentiles!D$4, "Medium", "High")) -> High | M26: =IF(H26 <Percentiles!$H$3, "Low", IF(H26 <= Percentiles!$H$4, "Medium", "High")) -> Medium | N26: =(F26 - AVERAGE(F$2:$F$70)) / _xlfn.STDEV.S(F$2:F$70) -> 1.453585 | O26: =(G26 - AVERAGE($G$2:G$70)) / _xlfn.STDEV.S(G$2:G$70) -> -1.0412266 | P26: =IF(AND(N26>=0, O26>=0), "Star", IF(AND(N26>=0, O26<0), "Cash Cow", IF(AND(N26<0, O26>=0), "Question Mark", "Dog"))) -> Cash Cow
